<mujoco model="humanoid">
  <compiler angle="radian" meshdir="meshes/"/>

  <asset>
    <mesh name="pelvis" content_type="model/stl" file="pelvis.STL"/>
    <mesh name="hip_roll_l_link" content_type="model/stl" file="hip_roll_l_link.STL"/>
    <mesh name="hip_yaw_l_link" content_type="model/stl" file="hip_yaw_l_link.STL"/>
    <mesh name="hip_pitch_l_link" content_type="model/stl" file="hip_pitch_l_link.STL"/>
    <mesh name="knee_pitch_l_link" content_type="model/stl" file="knee_pitch_l_link.STL"/>
    <mesh name="ankle_pitch_l_link" content_type="model/stl" file="ankle_pitch_l_link.STL"/>
    <mesh name="ankle_roll_l_link" content_type="model/stl" file="ankle_roll_l_link.STL"/>
    <mesh name="hip_roll_r_link" content_type="model/stl" file="hip_roll_r_link.STL"/>
    <mesh name="hip_yaw_r_link" content_type="model/stl" file="hip_yaw_r_link.STL"/>
    <mesh name="hip_pitch_r_link" content_type="model/stl" file="hip_pitch_r_link.STL"/>
    <mesh name="knee_pitch_r_link" content_type="model/stl" file="knee_pitch_r_link.STL"/>
    <mesh name="ankle_pitch_r_link" content_type="model/stl" file="ankle_pitch_r_link.STL"/>
    <mesh name="ankle_roll_r_link" content_type="model/stl" file="ankle_roll_r_link.STL"/>
    <mesh name="waist_link" content_type="model/stl" file="waist_link.STL"/>
    <mesh name="link0" content_type="model/stl" file="link0.STL"/>
    <mesh name="link1" content_type="model/stl" file="link1.STL"/>
    <mesh name="link2" content_type="model/stl" file="link2.STL"/>
    <mesh name="link3" content_type="model/stl" file="link3.STL"/>
    <mesh name="link4" content_type="model/stl" file="link4.STL"/>
    <mesh name="link5" content_type="model/stl" file="link5.STL"/>
    <mesh name="link6" content_type="model/stl" file="link6.STL"/>
    <mesh name="link7" content_type="model/stl" file="link7.STL"/>
    <mesh name="L_hand_base_link" content_type="model/stl" file="L_hand_base_link.STL"/>
    <mesh name="Link11_L" content_type="model/stl" file="Link11_L.STL"/>
    <mesh name="Link12_L" content_type="model/stl" file="Link12_L.STL"/>
    <mesh name="Link13_L" content_type="model/stl" file="Link13_L.STL"/>
    <mesh name="Link14_L" content_type="model/stl" file="Link14_L.STL"/>
    <mesh name="Link15_L" content_type="model/stl" file="Link15_L.STL"/>
    <mesh name="Link16_L" content_type="model/stl" file="Link16_L.STL"/>
    <mesh name="Link17_L" content_type="model/stl" file="Link17_L.STL"/>
    <mesh name="Link18_L" content_type="model/stl" file="Link18_L.STL"/>
    <mesh name="Link19_L" content_type="model/stl" file="Link19_L.STL"/>
    <mesh name="Link20_L" content_type="model/stl" file="Link20_L.STL"/>
    <mesh name="Link21_L" content_type="model/stl" file="Link21_L.STL"/>
    <mesh name="Link22_L" content_type="model/stl" file="Link22_L.STL"/>
    <mesh name="R_hand_base_link" content_type="model/stl" file="R_hand_base_link.STL"/>
    <mesh name="Link11_R" content_type="model/stl" file="Link11_R.STL"/>
    <mesh name="Link12_R" content_type="model/stl" file="Link12_R.STL"/>
    <mesh name="Link13_R" content_type="model/stl" file="Link13_R.STL"/>
    <mesh name="Link14_R" content_type="model/stl" file="Link14_R.STL"/>
    <mesh name="Link15_R" content_type="model/stl" file="Link15_R.STL"/>
    <mesh name="Link16_R" content_type="model/stl" file="Link16_R.STL"/>
    <mesh name="Link17_R" content_type="model/stl" file="Link17_R.STL"/>
    <mesh name="Link18_R" content_type="model/stl" file="Link18_R.STL"/>
    <mesh name="Link19_R" content_type="model/stl" file="Link19_R.STL"/>
    <mesh name="Link20_R" content_type="model/stl" file="Link20_R.STL"/>
    <mesh name="Link21_R" content_type="model/stl" file="Link21_R.STL"/>
    <mesh name="Link22_R" content_type="model/stl" file="Link22_R.STL"/>
  </asset>

  <worldbody>
    <body name="pelvis">
      <inertial pos="-0.05133 0 -0.03678" quat="0.60068 0.600576 -0.373132 0.373182" mass="5.22719" diaginertia="0.0901163 0.0756137 0.02488"/>
      <geom type="mesh" contype="0" conaffinity="0" group="1" density="0" rgba="0.752941 0.752941 0.752941 1" mesh="pelvis"/>
      <geom type="mesh" rgba="0.752941 0.752941 0.752941 1" mesh="pelvis"/>
      <body name="hip_roll_l_link" pos="0 0.13 -0.065923">
        <inertial pos="-0.00048 0.00336 -0.00372" quat="-0.170206 0.686316 -0.170206 0.686316" mass="1.12809" diaginertia="0.00113814 0.000871865 0.00058"/>
        <joint name="hip_roll_l_joint" pos="0 0 0" axis="1 0 0" range="-0.97 0.97" actuatorfrcrange="-150 150"/>
        <geom type="mesh" contype="0" conaffinity="0" group="1" density="0" rgba="0.752941 0.752941 0.752941 1" mesh="hip_roll_l_link"/>
        <geom type="mesh" rgba="0.752941 0.752941 0.752941 1" mesh="hip_roll_l_link"/>
        <body name="hip_yaw_l_link" pos="0 0 -0.116">
          <inertial pos="0.00104 0.00351 0.00968" quat="0.655486 -0.00856532 0.0207067 0.754874" mass="1.91605" diaginertia="0.00271913 0.00236314 0.00151773"/>
          <joint name="hip_yaw_l_joint" pos="0 0 0" axis="0 0 1" range="-1.0472 1.0472" actuatorfrcrange="-90 90"/>
          <geom type="mesh" contype="0" conaffinity="0" group="1" density="0" rgba="0.752941 0.752941 0.752941 1" mesh="hip_yaw_l_link"/>
          <geom type="mesh" rgba="0.752941 0.752941 0.752941 1" mesh="hip_yaw_l_link"/>
          <body name="hip_pitch_l_link">
            <inertial pos="0.00823 -0.00853 -0.13551" quat="0.891694 -0.0331991 0.0226408 0.450851" mass="3.37311" diaginertia="0.0231214 0.0223361 0.00626246"/>
            <joint name="hip_pitch_l_joint" pos="0 0 0" axis="0 1 0" range="-1.57 0.5236" actuatorfrcrange="-150 150"/>
            <geom type="mesh" contype="0" conaffinity="0" group="1" density="0" rgba="0.752941 0.752941 0.752941 1" mesh="hip_pitch_l_link"/>
            <geom type="mesh" rgba="0.752941 0.752941 0.752941 1" mesh="hip_pitch_l_link"/>
            <body name="knee_pitch_l_link" pos="0 0 -0.3">
              <inertial pos="0.00228 0.00293 -0.12066" quat="0.987279 0.0207788 -0.0159721 0.156825" mass="2.28832" diaginertia="0.0203626 0.0201507 0.000846692"/>
              <joint name="knee_pitch_l_joint" pos="0 0 0" axis="0 1 0" range="0 2.443" actuatorfrcrange="-150 150"/>
              <geom type="mesh" contype="0" conaffinity="0" group="1" density="0" rgba="0.752941 0.752941 0.752941 1" mesh="knee_pitch_l_link"/>
              <geom type="mesh" rgba="0.752941 0.752941 0.752941 1" mesh="knee_pitch_l_link"/>
              <body name="ankle_pitch_l_link" pos="0 0 -0.3">
                <inertial pos="0.00027 0 0" quat="0.5 0.5 -0.5 0.5" mass="0.15163" diaginertia="6e-05 3e-05 3e-05"/>
                <joint name="ankle_pitch_l_joint" pos="0 0 0" axis="0 1 0" range="-1.22 0.5236" actuatorfrcrange="-60 60"/>
                <geom type="mesh" contype="0" conaffinity="0" group="1" density="0" rgba="0.752941 0.752941 0.752941 1" mesh="ankle_pitch_l_link"/>
                <geom type="mesh" rgba="0.752941 0.752941 0.752941 1" mesh="ankle_pitch_l_link"/>
                <body name="ankle_roll_l_link">
                  <inertial pos="0.00229 0 -0.02723" quat="0 0.637136 0 0.770752" mass="0.74118" diaginertia="0.00262512 0.00233 0.000784878"/>
                  <joint name="ankle_roll_l_joint" pos="0 0 0" axis="1 0 0" range="-0.4363 0.4363" actuatorfrcrange="-30 30"/>
                  <geom type="mesh" contype="0" conaffinity="0" group="1" density="0" rgba="0.752941 0.752941 0.752941 1" mesh="ankle_roll_l_link"/>
                  <geom type="mesh" rgba="0.752941 0.752941 0.752941 1" mesh="ankle_roll_l_link"/>
                </body>
              </body>
            </body>
          </body>
        </body>
      </body>
      <body name="hip_roll_r_link" pos="0 -0.13 -0.065923">
        <inertial pos="-0.00048 -0.00336 -0.00372" quat="0.170206 0.686316 0.170206 0.686316" mass="1.12809" diaginertia="0.00113814 0.000871865 0.00058"/>
        <joint name="hip_roll_r_joint" pos="0 0 0" axis="1 0 0" range="-0.97 0.97" actuatorfrcrange="-150 150"/>
        <geom type="mesh" contype="0" conaffinity="0" group="1" density="0" rgba="0.752941 0.752941 0.752941 1" mesh="hip_roll_r_link"/>
        <geom type="mesh" rgba="0.752941 0.752941 0.752941 1" mesh="hip_roll_r_link"/>
        <body name="hip_yaw_r_link" pos="0 0 -0.116">
          <inertial pos="0.00104 -0.00351 0.00968" quat="0.754874 0.0207067 -0.00856532 0.655486" mass="1.91605" diaginertia="0.00271913 0.00236314 0.00151773"/>
          <joint name="hip_yaw_r_joint" pos="0 0 0" axis="0 0 1" range="-1.0472 1.0472" actuatorfrcrange="-90 90"/>
          <geom type="mesh" contype="0" conaffinity="0" group="1" density="0" rgba="0.752941 0.752941 0.752941 1" mesh="hip_yaw_r_link"/>
          <geom type="mesh" rgba="0.752941 0.752941 0.752941 1" mesh="hip_yaw_r_link"/>
          <body name="hip_pitch_r_link">
            <inertial pos="0.00823 0.00853 -0.13551" quat="0.450851 0.0226408 -0.0331991 0.891694" mass="3.37311" diaginertia="0.0231214 0.0223361 0.00626246"/>
            <joint name="hip_pitch_r_joint" pos="0 0 0" axis="0 1 0" range="-1.57 0.5236" actuatorfrcrange="-150 150"/>
            <geom type="mesh" contype="0" conaffinity="0" group="1" density="0" rgba="0.752941 0.752941 0.752941 1" mesh="hip_pitch_r_link"/>
            <geom type="mesh" rgba="0.752941 0.752941 0.752941 1" mesh="hip_pitch_r_link"/>
            <body name="knee_pitch_r_link" pos="0 0 -0.3">
              <inertial pos="0.00228 -0.00293 -0.12066" quat="0.987279 -0.0207788 -0.0159721 -0.156825" mass="2.28832" diaginertia="0.0203626 0.0201507 0.000846692"/>
              <joint name="knee_pitch_r_joint" pos="0 0 0" axis="0 1 0" range="0 2.443" actuatorfrcrange="-150 150"/>
              <geom type="mesh" contype="0" conaffinity="0" group="1" density="0" rgba="0.752941 0.752941 0.752941 1" mesh="knee_pitch_r_link"/>
              <geom type="mesh" rgba="0.752941 0.752941 0.752941 1" mesh="knee_pitch_r_link"/>
              <body name="ankle_pitch_r_link" pos="0 0 -0.3">
                <inertial pos="0.00027 0 0" quat="0.5 0.5 -0.5 0.5" mass="0.15163" diaginertia="6e-05 3e-05 3e-05"/>
                <joint name="ankle_pitch_r_joint" pos="0 0 0" axis="0 1 0" range="-1.22 0.5236" actuatorfrcrange="-60 60"/>
                <geom type="mesh" contype="0" conaffinity="0" group="1" density="0" rgba="0.752941 0.752941 0.752941 1" mesh="ankle_pitch_r_link"/>
                <geom type="mesh" rgba="0.752941 0.752941 0.752941 1" mesh="ankle_pitch_r_link"/>
                <body name="ankle_roll_r_link">
                  <inertial pos="0.00229 0 -0.02723" quat="0 0.637136 0 0.770752" mass="0.74118" diaginertia="0.00262512 0.00233 0.000784878"/>
                  <joint name="ankle_roll_r_joint" pos="0 0 0" axis="1 0 0" range="-0.4363 0.4363" actuatorfrcrange="-30 30"/>
                  <geom type="mesh" contype="0" conaffinity="0" group="1" density="0" rgba="0.752941 0.752941 0.752941 1" mesh="ankle_roll_r_link"/>
                  <geom type="mesh" rgba="0.752941 0.752941 0.752941 1" mesh="ankle_roll_r_link"/>
                </body>
              </body>
            </body>
          </body>
        </body>
      </body>
      <body name="waist_link" pos="-0.024 0 0.0062">
        <inertial pos="0.0835 0 0.27951" quat="0.999998 0.000361305 0.00104183 0.00185675" mass="14.41" diaginertia="0.520869 0.482971 0.123406"/>
        <geom type="mesh" contype="0" conaffinity="0" group="1" density="0" rgba="0.752941 0.752941 0.752941 1" mesh="waist_link"/>
        <geom type="mesh" rgba="0.752941 0.752941 0.752941 1" mesh="waist_link"/>
        <body name="shoulder_l_fixed_link" pos="0 0.15911 0.42582" quat="0.561136 -0.430264 0.430264 0.561135">
          <inertial pos="7e-06 -2e-06 -0.015501" mass="1.036" diaginertia="0.000836 0.000835 0.000658"/>
          <geom type="mesh" contype="0" conaffinity="0" group="1" density="0" rgba="0.752941 0.752941 0.752941 1" mesh="link0"/>
          <geom type="mesh" rgba="0.752941 0.752941 0.752941 1" mesh="link0"/>
          <body name="shoulder_pitch_l_link" pos="0 0 0.0767">
            <inertial pos="0 0.000725 -0.029524" quat="0.637041 0.77083 0 0" mass="0.222" diaginertia="0.000545 0.000513631 0.000270369"/>
            <joint name="shoulder_pitch_l_joint" pos="0 0 0" axis="0 0 1" range="-3.14159 0.785398" actuatorfrcrange="-40 40"/>
            <geom type="mesh" contype="0" conaffinity="0" group="1" density="0" rgba="0.752941 0.752941 0.752941 1" mesh="link1"/>
            <geom type="mesh" rgba="0.752941 0.752941 0.752941 1" mesh="link1"/>
            <body name="shoulder_roll_l_link" quat="0.5 0.5 -0.5 0.5">
              <inertial pos="0 -0.000473 0.006864" quat="0.999978 -0.00657738 0 0" mass="1.226" diaginertia="0.001198 0.00118004 0.000951961"/>
              <joint name="shoulder_roll_l_joint" pos="0 0 0" axis="0 0 1" range="-0.087 1.74533" actuatorfrcrange="-40 40"/>
              <geom type="mesh" contype="0" conaffinity="0" group="1" density="0" rgba="0.75294 0.75294 0.75294 1" mesh="link2"/>
              <geom type="mesh" rgba="0.75294 0.75294 0.75294 1" mesh="link2"/>
              <body name="shoulder_yaw_l_link" pos="0 -0.253 0" quat="0.707107 0.707107 0 0">
                <inertial pos="0.000247 0.003673 -0.081504" quat="0.999747 -0.0215591 0.000754078 0.00640175" mass="1.824" diaginertia="0.0142071 0.0139976 0.00129937"/>
                <joint name="shoulder_yaw_l_joint" pos="0 0 0" axis="0 0 1" range="-2.26893 2.26893" actuatorfrcrange="-22 22"/>
                <geom type="mesh" contype="0" conaffinity="0" group="1" density="0" rgba="0.752941 0.752941 0.752941 1" mesh="link3"/>
                <geom type="mesh" rgba="0.752941 0.752941 0.752941 1" mesh="link3"/>
                <body name="elbow_roll_l_link" quat="0.707107 -0.707107 0 0">
                  <inertial pos="0.002765 -0.020714 0.006089" quat="0.997296 -0.0356336 -0.00751368 0.0638332" mass="0.123" diaginertia="0.000241537 0.000210924 0.000124539"/>
                  <joint name="elbow_roll_l_joint" pos="0 0 0" axis="0 0 1" range="-2.26893 0.1" actuatorfrcrange="-22 22"/>
                  <geom type="mesh" contype="0" conaffinity="0" group="1" density="0" rgba="0.75294 0.75294 0.75294 1" mesh="link4"/>
                  <geom type="mesh" rgba="0.75294 0.75294 0.75294 1" mesh="link4"/>
                  <body name="elbow_yaw_l_link" pos="0 -0.2355 0" quat="0.707107 0.707107 0 0">
                    <inertial pos="0.000563 0.005092 -0.108798" quat="0.993172 -0.074755 0.0157112 0.088174" mass="1.01" diaginertia="0.00229232 0.00210921 0.000593467"/>
                    <joint name="elbow_yaw_l_joint" pos="0 0 0" axis="0 0 1" range="-2.26893 2.26893" actuatorfrcrange="-8 8"/>
                    <geom type="mesh" contype="0" conaffinity="0" group="1" density="0" rgba="0.752941 0.752941 0.752941 1" mesh="link5"/>
                    <geom type="mesh" rgba="0.752941 0.752941 0.752941 1" mesh="link5"/>
                    <body name="wrist_roll_l_link" quat="0.5 -0.5 -0.5 -0.5">
                      <inertial pos="0 -0.005048 0.000947" quat="0.609644 0.792675 0 0" mass="0.487" diaginertia="0.00027 0.000253187 0.000204813"/>
                      <joint name="wrist_roll_l_joint" pos="0 0 0" axis="0 0 1" range="-1.309 1.309" actuatorfrcrange="-8 8"/>
                      <geom type="mesh" contype="0" conaffinity="0" group="1" density="0" rgba="0.75294 0.75294 0.75294 1" mesh="link6"/>
                      <geom type="mesh" rgba="0.75294 0.75294 0.75294 1" mesh="link6"/>
                      <body name="wrist_pitch_l_joint" quat="0.5 -0.5 0.5 0.5">
                        <inertial pos="-1.6e-05 -0.06664 -0.015498" quat="0.614122 0.350505 -0.350505 0.614122" mass="0.228" diaginertia="0.00031698 0.000303 0.00011602"/>
                        <joint name="wrist_pitch_l_joint" pos="0 0 0" axis="0 0 1" range="-1.309 1.309" actuatorfrcrange="-8 8"/>
                        <geom type="mesh" contype="0" conaffinity="0" group="1" density="0" rgba="0.75294 0.75294 0.75294 1" mesh="link7"/>
                        <geom type="mesh" rgba="0.75294 0.75294 0.75294 1" mesh="link7"/>
                        <body name="L_hand_base_link" pos="0 -0.1115 0" quat="0.707107 0 -0.707107 0">
                          <inertial pos="-0.002551 -0.066047 -0.0019357" quat="0.992433 0.118422 0.021189 0.0245586" mass="0.14143" diaginertia="0.000123583 8.41243e-05 7.6759e-05"/>
                          <geom type="mesh" contype="0" conaffinity="0" group="1" density="0" rgba="0.1 0.1 0.1 1" mesh="L_hand_base_link"/>
                          <geom type="mesh" rgba="0.1 0.1 0.1 1" mesh="L_hand_base_link"/>
                          <body name="L_hand_tcp" pos="0 -0.145 0" quat="0.707107 0 -0.707107 0">
                            <body name="L_hand_tcp_out" quat="0 0.707107 -0.707107 0"/>
                          </body>
                          <body name="L_thumb_proximal_base" pos="-0.01696 -0.0691 0.02045" quat="0.499998 0.5 -0.5 0.500002">
                            <inertial pos="0.0048817 0.00038782 -0.00722" quat="0.445981 0.352284 0.495833 0.656617" mass="0.0018869" diaginertia="8.66031e-08 6.87331e-08 4.94199e-08"/>
                            <geom type="mesh" contype="0" conaffinity="0" group="1" density="0" rgba="0.1 0.1 0.1 1" mesh="Link11_L"/>
                            <geom type="mesh" rgba="0.1 0.1 0.1 1" mesh="Link11_L"/>
                            <body name="L_thumb_proximal" pos="0.0099867 0.0098242 -0.0089" quat="0.704571 -0.704573 -0.0598169 0.0598167">
                              <inertial pos="0.021936 -0.01279 -0.0080386" quat="0.25452 0.660687 -0.251949 0.659723" mass="0.0066101" diaginertia="2.78701e-06 2.44024e-06 8.6466e-07"/>
                              <geom type="mesh" contype="0" conaffinity="0" group="1" density="0" rgba="0.1 0.1 0.1 1" mesh="Link12_L"/>
                              <geom type="mesh" rgba="0.1 0.1 0.1 1" mesh="Link12_L"/>
                              <body name="L_thumb_intermediate" pos="0.04407 -0.034553 -0.0008">
                                <inertial pos="0.0095531 0.0016282 -0.0072002" quat="0.30738 0.636732 -0.307526 0.636803" mass="0.0037844" diaginertia="4.6532e-07 4.48114e-07 2.45646e-07"/>
                                <geom type="mesh" contype="0" conaffinity="0" group="1" density="0" rgba="0.1 0.1 0.1 1" mesh="Link13_L"/>
                                <geom type="mesh" rgba="0.1 0.1 0.1 1" mesh="Link13_L"/>
                                <body name="L_thumb_distal" pos="0.020248 -0.010156 -0.0012">
                                  <inertial pos="0.0092888 -0.004953 -0.0060033" quat="0.266264 0.65596 -0.262836 0.655544" mass="0.003344" diaginertia="2.0026e-07 1.95246e-07 8.1594e-08"/>
                                  <geom type="mesh" contype="0" conaffinity="0" group="1" density="0" rgba="0.1 0.1 0.1 1" mesh="Link14_L"/>
                                  <geom type="mesh" rgba="0.1 0.1 0.1 1" mesh="Link14_L"/>
                                </body>
                              </body>
                            </body>
                          </body>
                          <body name="L_index_proximal" pos="0.00028533 -0.13653 0.032268" quat="0.999848 -0.0174526 0 0">
                            <inertial pos="0.0012971 -0.011934 -0.0059998" quat="0.489677 0.510115 -0.489692 0.510099" mass="0.0042405" diaginertia="6.9402e-07 6.62904e-07 2.10916e-07"/>
                            <geom type="mesh" contype="0" conaffinity="0" group="1" density="0" rgba="0.1 0.1 0.1 1" mesh="Link15_L"/>
                            <geom type="mesh" rgba="0.1 0.1 0.1 1" mesh="Link15_L"/>
                            <body name="L_index_intermediate" pos="-0.0024229 -0.032041 -0.001">
                              <inertial pos="0.0021753 -0.019567 -0.005" quat="0.528694 0.469555 -0.528694 0.469555" mass="0.0045682" diaginertia="7.8176e-07 7.72427e-07 8.47209e-08"/>
                              <geom type="mesh" contype="0" conaffinity="0" group="1" density="0" rgba="0.1 0.1 0.1 1" mesh="Link16_L"/>
                              <geom type="mesh" rgba="0.1 0.1 0.1 1" mesh="Link16_L"/>
                            </body>
                          </body>
                          <body name="L_middle_proximal" pos="0.00028533 -0.1371 0.01295">
                            <inertial pos="0.0012971 -0.011934 -0.0059999" quat="0.489677 0.510115 -0.489692 0.510099" mass="0.0042405" diaginertia="6.9402e-07 6.62904e-07 2.10916e-07"/>
                            <geom type="mesh" contype="0" conaffinity="0" group="1" density="0" rgba="0.1 0.1 0.1 1" mesh="Link17_L"/>
                            <geom type="mesh" rgba="0.1 0.1 0.1 1" mesh="Link17_L"/>
                            <body name="L_middle_intermediate" pos="-0.0024229 -0.032041 -0.001">
                              <inertial pos="0.001921 -0.020796 -0.0049999" quat="0.531603 0.466115 -0.531728 0.466262" mass="0.0050397" diaginertia="9.8385e-07 9.73288e-07 9.14016e-08"/>
                              <geom type="mesh" contype="0" conaffinity="0" group="1" density="0" rgba="0.1 0.1 0.1 1" mesh="Link18_L"/>
                              <geom type="mesh" rgba="0.1 0.1 0.1 1" mesh="Link18_L"/>
                            </body>
                          </body>
                          <body name="L_ring_proximal" pos="0.00028533 -0.13691 -0.0062872" quat="0.999657 0.026177 0 0">
                            <inertial pos="0.0012971 -0.011934 -0.0059999" quat="0.489677 0.510114 -0.489692 0.510099" mass="0.0042405" diaginertia="6.9402e-07 6.62904e-07 2.10916e-07"/>
                            <geom type="mesh" contype="0" conaffinity="0" group="1" density="0" rgba="0.1 0.1 0.1 1" mesh="Link19_L"/>
                            <geom type="mesh" rgba="0.1 0.1 0.1 1" mesh="Link19_L"/>
                            <body name="L_ring_intermediate" pos="-0.0024229 -0.032041 -0.001">
                              <inertial pos="0.0021753 -0.019567 -0.005" quat="0.528694 0.469556 -0.528694 0.469556" mass="0.0045682" diaginertia="7.8176e-07 7.72437e-07 8.47208e-08"/>
                              <geom type="mesh" contype="0" conaffinity="0" group="1" density="0" rgba="0.1 0.1 0.1 1" mesh="Link20_L"/>
                              <geom type="mesh" rgba="0.1 0.1 0.1 1" mesh="Link20_L"/>
                            </body>
                          </body>
                          <body name="L_pinky_proximal" pos="0.00028533 -0.13571 -0.025488" quat="0.99863 0.0523361 0 0">
                            <inertial pos="0.0012971 -0.011934 -0.0059999" quat="0.489677 0.510114 -0.489692 0.510099" mass="0.0042405" diaginertia="6.9402e-07 6.62904e-07 2.10916e-07"/>
                            <geom type="mesh" contype="0" conaffinity="0" group="1" density="0" rgba="0.1 0.1 0.1 1" mesh="Link21_L"/>
                            <geom type="mesh" rgba="0.1 0.1 0.1 1" mesh="Link21_L"/>
                            <body name="L_pinky_intermediate" pos="-0.0024229 -0.032041 -0.001">
                              <inertial pos="0.0024788 -0.016208 -0.0050001" quat="0.526797 0.471683 -0.526793 0.471687" mass="0.0036036" diaginertia="4.4881e-07 4.43809e-07 6.5736e-08"/>
                              <geom type="mesh" contype="0" conaffinity="0" group="1" density="0" rgba="0.1 0.1 0.1 1" mesh="Link22_L"/>
                              <geom type="mesh" rgba="0.1 0.1 0.1 1" mesh="Link22_L"/>
                            </body>
                          </body>
                        </body>
                      </body>
                    </body>
                  </body>
                </body>
              </body>
            </body>
          </body>
        </body>
        <body name="shoulder_r_fixed_link" pos="0 -0.15911 0.42582" quat="0.561136 0.430264 0.430264 -0.561135">
          <inertial pos="7e-06 2e-06 0.015501" mass="1.036" diaginertia="0.000836 0.000835 0.000658"/>
          <geom type="mesh" contype="0" conaffinity="0" group="1" density="0" rgba="0.752941 0.752941 0.752941 1" mesh="link0"/>
          <geom type="mesh" rgba="0.752941 0.752941 0.752941 1" mesh="link0"/>
          <body name="shoulder_pitch_r_link" pos="0 0 0.0767">
            <inertial pos="0 -0.000725 -0.029524" quat="0.77083 0.637041 0 0" mass="0.222" diaginertia="0.000545 0.000513631 0.000270369"/>
            <joint name="shoulder_pitch_r_joint" pos="0 0 0" axis="0 0 1" range="-0.785398 3.14159" actuatorfrcrange="-40 40"/>
            <geom type="mesh" contype="0" conaffinity="0" group="1" density="0" rgba="0.752941 0.752941 0.752941 1" mesh="link1"/>
            <geom type="mesh" rgba="0.752941 0.752941 0.752941 1" mesh="link1"/>
            <body name="shoulder_roll_r_link" quat="0.5 -0.5 -0.5 -0.5">
              <inertial pos="0 0.000473 0.006864" quat="0.999978 0.00657738 0 0" mass="1.226" diaginertia="0.001198 0.00118004 0.000951961"/>
              <joint name="shoulder_roll_r_joint" pos="0 0 0" axis="0 0 1" range="-1.74533 0.087" actuatorfrcrange="-40 40"/>
              <geom quat="2.67949e-08 0 0 1" type="mesh" contype="0" conaffinity="0" group="1" density="0" rgba="0.75294 0.75294 0.75294 1" mesh="link2"/>
              <geom quat="2.67949e-08 0 0 1" type="mesh" rgba="0.75294 0.75294 0.75294 1" mesh="link2"/>
              <body name="shoulder_yaw_r_link" pos="0 0.253 0" quat="0.707107 -0.707107 0 0">
                <inertial pos="0.000247 -0.003673 -0.081504" quat="0.999747 0.0215591 0.000754078 -0.00640175" mass="1.824" diaginertia="0.0142071 0.0139976 0.00129937"/>
                <joint name="shoulder_yaw_r_joint" pos="0 0 0" axis="0 0 1" range="-2.26893 2.26893" actuatorfrcrange="-22 22"/>
                <geom type="mesh" contype="0" conaffinity="0" group="1" density="0" rgba="0.752941 0.752941 0.752941 1" mesh="link3"/>
                <geom type="mesh" rgba="0.752941 0.752941 0.752941 1" mesh="link3"/>
                <body name="elbow_roll_r_link" quat="0.707107 0.707107 0 0">
                  <inertial pos="0.002765 0.020714 0.006089" quat="0.997296 0.0356336 -0.00751368 -0.0638332" mass="0.123" diaginertia="0.000241537 0.000210924 0.000124539"/>
                  <joint name="elbow_roll_r_joint" pos="0 0 0" axis="0 0 1" range="-0.1 2.26893" actuatorfrcrange="-22 22"/>
                  <geom quat="2.67949e-08 0 0 1" type="mesh" contype="0" conaffinity="0" group="1" density="0" rgba="0.75294 0.75294 0.75294 1" mesh="link4"/>
                  <geom quat="2.67949e-08 0 0 1" type="mesh" rgba="0.75294 0.75294 0.75294 1" mesh="link4"/>
                  <body name="elbow_yaw_r_link" pos="0 0.2355 0" quat="0.707107 -0.707107 0 0">
                    <inertial pos="0.000563 -0.005092 -0.108798" quat="0.995124 0.0767573 0.00673248 0.0615803" mass="1.01" diaginertia="0.0022895 0.00211237 0.000593133"/>
                    <joint name="elbow_yaw_r_joint" pos="0 0 0" axis="0 0 1" range="-2.26893 2.26893" actuatorfrcrange="-8 8"/>
                    <geom type="mesh" contype="0" conaffinity="0" group="1" density="0" rgba="0.752941 0.752941 0.752941 1" mesh="link5"/>
                    <geom type="mesh" rgba="0.752941 0.752941 0.752941 1" mesh="link5"/>
                    <body name="wrist_roll_r_link" quat="0.5 0.5 -0.5 0.5">
                      <inertial pos="0 0.005048 0.000947" quat="0.792675 0.609644 0 0" mass="0.487" diaginertia="0.00027 0.000253187 0.000204813"/>
                      <joint name="wrist_roll_r_joint" pos="0 0 0" axis="0 0 1" range="-1.309 1.309" actuatorfrcrange="-8 8"/>
                      <geom quat="2.67949e-08 1 0 0" type="mesh" contype="0" conaffinity="0" group="1" density="0" rgba="0.75294 0.75294 0.75294 1" mesh="link6"/>
                      <geom quat="2.67949e-08 1 0 0" type="mesh" rgba="0.75294 0.75294 0.75294 1" mesh="link6"/>
                      <body name="wrist_pitch_r_link" quat="0.5 0.5 -0.5 0.5">
                        <inertial pos="-1.6e-05 -0.06664 -0.015498" quat="0.614122 0.350505 -0.350505 0.614122" mass="0.228" diaginertia="0.00031698 0.000303 0.00011602"/>
                        <joint name="wrist_pitch_r_joint" pos="0 0 0" axis="0 0 1" range="-1.309 1.309" actuatorfrcrange="-8 8"/>
                        <geom type="mesh" contype="0" conaffinity="0" group="1" density="0" rgba="0.75294 0.75294 0.75294 1" mesh="link7"/>
                        <geom type="mesh" rgba="0.75294 0.75294 0.75294 1" mesh="link7"/>
                        <body name="R_hand_base_link" pos="0 -0.1115 0" quat="0.707107 0 -0.707107 0">
                          <inertial pos="-0.0025264 -0.066047 0.0019598" quat="0.993005 -0.113528 -0.0210604 0.0246792" mass="0.14143" diaginertia="0.000122991 8.41186e-05 7.61951e-05"/>
                          <geom type="mesh" contype="0" conaffinity="0" group="1" density="0" rgba="0.1 0.1 0.1 1" mesh="R_hand_base_link"/>
                          <geom type="mesh" rgba="0.1 0.1 0.1 1" mesh="R_hand_base_link"/>
                          <body name="R_hand_tcp" pos="0 -0.145 0" quat="0.707107 0 -0.707107 0">
                            <body name="R_hand_tcp_out" quat="0 0.707107 -0.707107 0"/>
                          </body>
                          <body name="R_thumb_proximal_base" pos="-0.01696 -0.0691 -0.02045" quat="0.499998 0.5 -0.5 0.500002">
                            <inertial pos="-0.0048064 0.0009382 -0.00757" quat="0.515015 0.680854 0.408023 0.323596" mass="0.0018869" diaginertia="8.66026e-08 6.8732e-08 4.94194e-08"/>
                            <geom type="mesh" contype="0" conaffinity="0" group="1" density="0" rgba="0.1 0.1 0.1 1" mesh="Link11_R"/>
                            <geom type="mesh" rgba="0.1 0.1 0.1 1" mesh="Link11_R"/>
                            <body name="R_thumb_proximal" pos="-0.0088099 0.010892 -0.00925" quat="0.0996843 0.0996847 0.700046 0.700044">
                              <inertial pos="0.021932 0.012785 -0.0080386" quat="-0.254474 0.660716 0.251893 0.659733" mass="0.0066075" diaginertia="2.78601e-06 2.43933e-06 8.64566e-07"/>
                              <geom type="mesh" contype="0" conaffinity="0" group="1" density="0" rgba="0.1 0.1 0.1 1" mesh="Link12_R"/>
                              <geom type="mesh" rgba="0.1 0.1 0.1 1" mesh="Link12_R"/>
                              <body name="R_thumb_intermediate" pos="0.04407 0.034553 -0.0008">
                                <inertial pos="0.0095544 -0.0016282 -0.0071997" quat="0.636718 0.307389 -0.636802 0.307548" mass="0.0037847" diaginertia="4.6531e-07 4.48089e-07 2.45661e-07"/>
                                <geom type="mesh" contype="0" conaffinity="0" group="1" density="0" rgba="0.1 0.1 0.1 1" mesh="Link13_R"/>
                                <geom type="mesh" rgba="0.1 0.1 0.1 1" mesh="Link13_R"/>
                                <body name="R_thumb_distal" pos="0.020248 0.010156 -0.0012">
                                  <inertial pos="0.0092888 0.0049529 -0.0060033" quat="-0.266294 0.655967 0.262806 0.655537" mass="0.0033441" diaginertia="2.0026e-07 1.95247e-07 8.1593e-08"/>
                                  <geom type="mesh" contype="0" conaffinity="0" group="1" density="0" rgba="0.1 0.1 0.1 1" mesh="Link14_R"/>
                                  <geom type="mesh" rgba="0.1 0.1 0.1 1" mesh="Link14_R"/>
                                </body>
                              </body>
                            </body>
                          </body>
                          <body name="R_index_proximal" pos="0.00028533 -0.13653 -0.032268" quat="0.0174454 -0.999848 0 0">
                            <inertial pos="0.0012259 0.011942 -0.0060001" quat="0.50867 0.49121 -0.508643 0.491172" mass="0.0042403" diaginertia="6.9398e-07 6.62871e-07 2.10909e-07"/>
                            <geom type="mesh" contype="0" conaffinity="0" group="1" density="0" rgba="0.1 0.1 0.1 1" mesh="Link15_R"/>
                            <geom type="mesh" rgba="0.1 0.1 0.1 1" mesh="Link15_R"/>
                            <body name="R_index_intermediate" pos="-0.0026138 0.032026 -0.001">
                              <inertial pos="0.0019697 0.019589 -0.005" quat="0.466773 0.531152 -0.466773 0.531153" mass="0.0045683" diaginertia="7.8179e-07 7.72465e-07 8.47212e-08"/>
                              <geom type="mesh" contype="0" conaffinity="0" group="1" density="0" rgba="0.1 0.1 0.1 1" mesh="Link16_R"/>
                              <geom type="mesh" rgba="0.1 0.1 0.1 1" mesh="Link16_R"/>
                            </body>
                          </body>
                          <body name="R_middle_proximal" pos="0.00028533 -0.1371 -0.01295" quat="-3.67321e-06 -1 0 0">
                            <inertial pos="0.001297 0.011934 -0.0060001" quat="0.510131 0.489693 -0.510105 0.489653" mass="0.0042403" diaginertia="6.9397e-07 6.62865e-07 2.10915e-07"/>
                            <geom type="mesh" contype="0" conaffinity="0" group="1" density="0" rgba="0.1 0.1 0.1 1" mesh="Link17_R"/>
                            <geom type="mesh" rgba="0.1 0.1 0.1 1" mesh="Link17_R"/>
                            <body name="R_middle_intermediate" pos="-0.0024229 0.032041 -0.001">
                              <inertial pos="0.001921 0.020796 -0.005" quat="0.466148 0.531627 -0.466229 0.531705" mass="0.0050396" diaginertia="9.8384e-07 9.73279e-07 9.14014e-08"/>
                              <geom type="mesh" contype="0" conaffinity="0" group="1" density="0" rgba="0.1 0.1 0.1 1" mesh="Link18_R"/>
                              <geom type="mesh" rgba="0.1 0.1 0.1 1" mesh="Link18_R"/>
                            </body>
                          </body>
                          <body name="R_ring_proximal" pos="0.00028533 -0.13691 0.0062872" quat="0.0261933 0.999657 0 0">
                            <inertial pos="0.001297 0.011934 -0.0060002" quat="0.510129 0.489691 -0.510107 0.489654" mass="0.0042403" diaginertia="6.9397e-07 6.62865e-07 2.10915e-07"/>
                            <geom type="mesh" contype="0" conaffinity="0" group="1" density="0" rgba="0.1 0.1 0.1 1" mesh="Link19_R"/>
                            <geom type="mesh" rgba="0.1 0.1 0.1 1" mesh="Link19_R"/>
                            <body name="R_ring_intermediate" pos="-0.0024229 0.032041 -0.001">
                              <inertial pos="0.0021753 0.019567 -0.005" quat="0.469554 0.528695 -0.469554 0.528695" mass="0.0045683" diaginertia="7.8177e-07 7.72448e-07 8.4722e-08"/>
                              <geom type="mesh" contype="0" conaffinity="0" group="1" density="0" rgba="0.1 0.1 0.1 1" mesh="Link20_R"/>
                              <geom type="mesh" rgba="0.1 0.1 0.1 1" mesh="Link20_R"/>
                            </body>
                          </body>
                          <body name="R_pinky_proximal" pos="0.00028533 -0.13571 0.025488" quat="0.0523224 0.99863 0 0">
                            <inertial pos="0.001297 0.011934 -0.0060001" quat="0.51013 0.489693 -0.510106 0.489653" mass="0.0042403" diaginertia="6.9397e-07 6.62865e-07 2.10915e-07"/>
                            <geom type="mesh" contype="0" conaffinity="0" group="1" density="0" rgba="0.1 0.1 0.1 1" mesh="Link21_R"/>
                            <geom type="mesh" rgba="0.1 0.1 0.1 1" mesh="Link21_R"/>
                            <body name="R_pinky_intermediate" pos="-0.0024229 0.032041 -0.001">
                              <inertial pos="0.0024748 0.016203 -0.0050031" quat="0.47398 0.528862 -0.469291 0.524799" mass="0.0035996" diaginertia="4.4867e-07 4.43723e-07 6.56538e-08"/>
                              <geom type="mesh" contype="0" conaffinity="0" group="1" density="0" rgba="0.1 0.1 0.1 1" mesh="Link22_R"/>
                              <geom type="mesh" rgba="0.1 0.1 0.1 1" mesh="Link22_R"/>
                            </body>
                          </body>
                        </body>
                      </body>
                    </body>
                  </body>
                </body>
              </body>
            </body>
          </body>
        </body>
      </body>
    </body>
  </worldbody>
</mujoco>
